Workbook

Sheet Data
A1: Veličina | B1: Hodnota | C1: Jednotka | D1: Význam
A2: U | B2: 35 | C2: V | D2: Efektivní hodnota napájecího napětí
A3: L₁ | B3: 0.036 | C3: H | D3: Indukčnost první cívky
A4: R₁ | B4: 32 | C4: Ω | D4: Odpor první cívky
A5: L₂ | B5: 0.041 | C5: H | D5: Indukčnost druhé cívky
A6: R₂ | B6: 24 | C6: Ω | D6: Odpor druhé cívky
A7: P | B7: 2.1 | C7: W | D7: Požadovaný činný výkon
A8: Δf | B8: 5 | C8: Hz | D8: Základní krok dat grafu
A9: fₘₐₓ | B9: 600 | C9: Hz | D9: Horní mez grafu

Sheet Výpočty
A1: Veličina | B1: Vzorec / hodnota | C1: Jednotka | D1: Poznámka
A2: R | B2: =Data!B4+Data!B6 -> 56 | C2: Ω | D2: Celkový sériový odpor
A3: L | B3: =Data!B3+Data!B5 -> 0.077 | C3: H | D3: Celková indukčnost
A4: I – přesně | B4: =SQRT(Data!B7/B2) -> 0.19364917 | C4: A | D4: Proud bez průběžného zaokrouhlení
A5: f – přesně | B5: =SQRT(Data!B2^2*B2/Data!B7-B2^2)/(2*PI()*B3) -> 355.19434 | C5: Hz | D5: Přesný průsečík P(f)=2,1 W
A6: R – zaokr. | B6: =ROUND(Data!B4+Data!B6,3) -> 56 | C6: Ω | D6: Průběžně zaokrouhlený odpor
A7: L – zaokr. | B7: =ROUND(ROUND((Data!B3+Data!B5)*1000,3)/1000,3) -> 0.077 | C7: H | D7: Průběžně zaokrouhlená indukčnost
A8: I – zaokr. | B8: =ROUND(SQRT(Data!B7/B6),3) -> 0.194 | C8: A | D8: Výsledek použitý v protokolu
A9: U_R | B9: =ROUND(B8*B6,3) -> 10.864 | C9: V | D9: Napětí na odporové části
A10: U_L | B10: =ROUND(SQRT(Data!B2^2-B9^2),3) -> 33.271 | C10: V | D10: Napětí na induktivní části
A11: X_L | B11: =ROUND(B10/B8,3) -> 171.5 | C11: Ω | D11: Induktivní reaktance
A12: f – protokol | B12: =ROUND(B11/(2*PI()*B7),3) -> 354.481 | C12: Hz | D12: Průběžně zaokrouhlený výsledek
A13: P při f protokolu | B13: =Data!B2^2*B6/(B6^2+(2*PI()*B12*B7)^2) -> 2.1076452 | C13: W | D13: Kontrolní výkon 2,108 W

Sheet Graf
A1: f [Hz] | B1: P(f) [W] | C1: P požadovaný = 2,100 W | D1: Přesný: 355,194 Hz; 2,100 W | E1: Protokol: 354,481 Hz; 2,108 W
A2: 0 | B2: =Data!B2^2*(Data!B4+Data!B6)/((Data!B4+Data!B6)^2+(2*PI()*A2*(Data!B3+Data!B5))^2) -> 21.875 | C2: =Data!B7 -> 2.1
A3: 5 | B3: =Data!B2^2*(Data!B4+Data!B6)/((Data!B4+Data!B6)^2+(2*PI()*A3*(Data!B3+Data!B5))^2) -> 21.834258 | C3: =Data!B7 -> 2.1
A4: 10 | B4: =Data!B2^2*(Data!B4+Data!B6)/((Data!B4+Data!B6)^2+(2*PI()*A4*(Data!B3+Data!B5))^2) -> 21.712937 | C4: =Data!B7 -> 2.1
A5: 15 | B5: =Data!B2^2*(Data!B4+Data!B6)/((Data!B4+Data!B6)^2+(2*PI()*A5*(Data!B3+Data!B5))^2) -> 21.513704 | C5: =Data!B7 -> 2.1
A6: 20 | B6: =Data!B2^2*(Data!B4+Data!B6)/((Data!B4+Data!B6)^2+(2*PI()*A6*(Data!B3+Data!B5))^2) -> 21.240843 | C6: =Data!B7 -> 2.1
A7: 25 | B7: =Data!B2^2*(Data!B4+Data!B6)/((Data!B4+Data!B6)^2+(2*PI()*A7*(Data!B3+Data!B5))^2) -> 20.900028 | C7: =Data!B7 -> 2.1
A8: 30 | B8: =Data!B2^2*(Data!B4+Data!B6)/((Data!B4+Data!B6)^2+(2*PI()*A8*(Data!B3+Data!B5))^2) -> 20.498044 | C8: =Data!B7 -> 2.1
A9: 35 | B9: =Data!B2^2*(Data!B4+Data!B6)/((Data!B4+Data!B6)^2+(2*PI()*A9*(Data!B3+Data!B5))^2) -> 20.042465 | C9: =Data!B7 -> 2.1
A10: 40 | B10: =Data!B2^2*(Data!B4+Data!B6)/((Data!B4+Data!B6)^2+(2*PI()*A10*(Data!B3+Data!B5))^2) -> 19.541331 | C10: =Data!B7 -> 2.1
A11: 45 | B11: =Data!B2^2*(Data!B4+Data!B6)/((Data!B4+Data!B6)^2+(2*PI()*A11*(Data!B3+Data!B5))^2) -> 19.00284 | C11: =Data!B7 -> 2.1
A12: 50 | B12: =Data!B2^2*(Data!B4+Data!B6)/((Data!B4+Data!B6)^2+(2*PI()*A12*(Data!B3+Data!B5))^2) -> 18.435068 | C12: =Data!B7 -> 2.1
A13: 55 | B13: =Data!B2^2*(Data!B4+Data!B6)/((Data!B4+Data!B6)^2+(2*PI()*A13*(Data!B3+Data!B5))^2) -> 17.845742 | C13: =Data!B7 -> 2.1
A14: 60 | B14: =Data!B2^2*(Data!B4+Data!B6)/((Data!B4+Data!B6)^2+(2*PI()*A14*(Data!B3+Data!B5))^2) -> 17.242059 | C14: =Data!B7 -> 2.1
A15: 65 | B15: =Data!B2^2*(Data!B4+Data!B6)/((Data!B4+Data!B6)^2+(2*PI()*A15*(Data!B3+Data!B5))^2) -> 16.630564 | C15: =Data!B7 -> 2.1
A16: 70 | B16: =Data!B2^2*(Data!B4+Data!B6)/((Data!B4+Data!B6)^2+(2*PI()*A16*(Data!B3+Data!B5))^2) -> 16.017069 | C16: =Data!B7 -> 2.1
A17: 75 | B17: =Data!B2^2*(Data!B4+Data!B6)/((Data!B4+Data!B6)^2+(2*PI()*A17*(Data!B3+Data!B5))^2) -> 15.406625 | C17: =Data!B7 -> 2.1
A18: 80 | B18: =Data!B2^2*(Data!B4+Data!B6)/((Data!B4+Data!B6)^2+(2*PI()*A18*(Data!B3+Data!B5))^2) -> 14.803522 | C18: =Data!B7 -> 2.1
A19: 85 | B19: =Data!B2^2*(Data!B4+Data!B6)/((Data!B4+Data!B6)^2+(2*PI()*A19*(Data!B3+Data!B5))^2) -> 14.21132 | C19: =Data!B7 -> 2.1
A20: 90 | B20: =Data!B2^2*(Data!B4+Data!B6)/((Data!B4+Data!B6)^2+(2*PI()*A20*(Data!B3+Data!B5))^2) -> 13.632894 | C20: =Data!B7 -> 2.1
A21: 95 | B21: =Data!B2^2*(Data!B4+Data!B6)/((Data!B4+Data!B6)^2+(2*PI()*A21*(Data!B3+Data!B5))^2) -> 13.070502 | C21: =Data!B7 -> 2.1
A22: 100 | B22: =Data!B2^2*(Data!B4+Data!B6)/((Data!B4+Data!B6)^2+(2*PI()*A22*(Data!B3+Data!B5))^2) -> 12.525847 | C22: =Data!B7 -> 2.1
A23: 105 | B23: =Data!B2^2*(Data!B4+Data!B6)/((Data!B4+Data!B6)^2+(2*PI()*A23*(Data!B3+Data!B5))^2) -> 12.000151 | C23: =Data!B7 -> 2.1
A24: 110 | B24: =Data!B2^2*(Data!B4+Data!B6)/((Data!B4+Data!B6)^2+(2*PI()*A24*(Data!B3+Data!B5))^2) -> 11.49422 | C24: =Data!B7 -> 2.1
A25: 115 | B25: =Data!B2^2*(Data!B4+Data!B6)/((Data!B4+Data!B6)^2+(2*PI()*A25*(Data!B3+Data!B5))^2) -> 11.008509 | C25: =Data!B7 -> 2.1
A26: 120 | B26: =Data!B2^2*(Data!B4+Data!B6)/((Data!B4+Data!B6)^2+(2*PI()*A26*(Data!B3+Data!B5))^2) -> 10.543185 | C26: =Data!B7 -> 2.1
A27: 125 | B27: =Data!B2^2*(Data!B4+Data!B6)/((Data!B4+Data!B6)^2+(2*PI()*A27*(Data!B3+Data!B5))^2) -> 10.098177 | C27: =Data!B7 -> 2.1
A28: 130 | B28: =Data!B2^2*(Data!B4+Data!B6)/((Data!B4+Data!B6)^2+(2*PI()*A28*(Data!B3+Data!B5))^2) -> 9.6732236 | C28: =Data!B7 -> 2.1
A29: 135 | B29: =Data!B2^2*(Data!B4+Data!B6)/((Data!B4+Data!B6)^2+(2*PI()*A29*(Data!B3+Data!B5))^2) -> 9.2679146 | C29: =Data!B7 -> 2.1
A30: 140 | B30: =Data!B2^2*(Data!B4+Data!B6)/((Data!B4+Data!B6)^2+(2*PI()*A30*(Data!B3+Data!B5))^2) -> 8.8817263 | C30: =Data!B7 -> 2.1
A31: 145 | B31: =Data!B2^2*(Data!B4+Data!B6)/((Data!B4+Data!B6)^2+(2*PI()*A31*(Data!B3+Data!B5))^2) -> 8.5140501 | C31: =Data!B7 -> 2.1
A32: 150 | B32: =Data!B2^2*(Data!B4+Data!B6)/((Data!B4+Data!B6)^2+(2*PI()*A32*(Data!B3+Data!B5))^2) -> 8.1642178 | C32: =Data!B7 -> 2.1
A33: 155 | B33: =Data!B2^2*(Data!B4+Data!B6)/((Data!B4+Data!B6)^2+(2*PI()*A33*(Data!B3+Data!B5))^2) -> 7.8315217 | C33: =Data!B7 -> 2.1
A34: 160 | B34: =Data!B2^2*(Data!B4+Data!B6)/((Data!B4+Data!B6)^2+(2*PI()*A34*(Data!B3+Data!B5))^2) -> 7.5152312 | C34: =Data!B7 -> 2.1
A35: 165 | B35: =Data!B2^2*(Data!B4+Data!B6)/((Data!B4+Data!B6)^2+(2*PI()*A35*(Data!B3+Data!B5))^2) -> 7.214606 | C35: =Data!B7 -> 2.1
A36: 170 | B36: =Data!B2^2*(Data!B4+Data!B6)/((Data!B4+Data!B6)^2+(2*PI()*A36*(Data!B3+Data!B5))^2) -> 6.9289067 | C36: =Data!B7 -> 2.1
A37: 175 | B37: =Data!B2^2*(Data!B4+Data!B6)/((Data!B4+Data!B6)^2+(2*PI()*A37*(Data!B3+Data!B5))^2) -> 6.657403 | C37: =Data!B7 -> 2.1
A38: 180 | B38: =Data!B2^2*(Data!B4+Data!B6)/((Data!B4+Data!B6)^2+(2*PI()*A38*(Data!B3+Data!B5))^2) -> 6.3993801 | C38: =Data!B7 -> 2.1
A39: 185 | B39: =Data!B2^2*(Data!B4+Data!B6)/((Data!B4+Data!B6)^2+(2*PI()*A39*(Data!B3+Data!B5))^2) -> 6.1541434 | C39: =Data!B7 -> 2.1
A40: 190 | B40: =Data!B2^2*(Data!B4+Data!B6)/((Data!B4+Data!B6)^2+(2*PI()*A40*(Data!B3+Data!B5))^2) -> 5.9210218 | C40: =Data!B7 -> 2.1
...
